using System.Diagnostics.CodeAnalysis;
using Xunit;
using Xunit.Sdk;

namespace Funcky;

public static partial class FunctionalAssert
{
    /// <summary>Asserts that the given <paramref name="result"/> is <c>Ok</c> and contains the given <paramref name="expectedResult"/>.</summary>
    /// <exception cref="AssertActualExpectedException">Thrown when <paramref name="result"/> is <c>Error</c>.</exception>
#if STACK_TRACE_HIDDEN_SUPPORTED
    [System.Diagnostics.StackTraceHidden]
#else
    [System.Runtime.CompilerServices.MethodImpl(System.Runtime.CompilerServices.MethodImplOptions.AggressiveInlining)]
#endif
    public static void Ok<TValidResult>(TValidResult expectedResult, Result<TValidResult> result)
        where TValidResult : notnull
    {
        try
        {
            Assert.Equal(expectedResult, result);
        }
        catch (EqualException exception)
        {
            throw new AssertActualExpectedException(
                expected: exception.Expected,
                actual: exception.Actual,
                userMessage: $"{nameof(FunctionalAssert)}.{nameof(Ok)}() Failure");
        }
    }

    /// <summary>Asserts that the given <paramref name="result"/> is <c>Ok</c>.</summary>
    /// <exception cref="AssertActualExpectedException">Thrown when <paramref name="result"/> is <c>Error</c>.</exception>
    /// <returns>Returns the value in <paramref name="result"/> if it was <c>Ok</c>.</returns>
#if STACK_TRACE_HIDDEN_SUPPORTED
    [System.Diagnostics.StackTraceHidden]
#else
    [System.Runtime.CompilerServices.MethodImpl(System.Runtime.CompilerServices.MethodImplOptions.AggressiveInlining)]
#endif
    [SuppressMessage("Microsoft.Usage", "CA2200", Justification = "Stack trace erasure intentional.")]
    [SuppressMessage("ReSharper", "PossibleIntendedRethrow", Justification = "Stack trace erasure intentional.")]
    public static TValidResult Ok<TValidResult>(Result<TValidResult> result)
        where TValidResult : notnull
    {
        try
        {
            return result.GetOrElse(
                static exception => throw new AssertActualExpectedException(
                    expected: "Ok(...)",
                    actual: $"Error({FormatException(exception)})",
                    userMessage: $"{nameof(FunctionalAssert)}.{nameof(Ok)}() Failure"));
        }
        catch (AssertActualExpectedException exception)
        {
            throw exception;
        }
    }

    private static string FormatException(Exception exception)
        => $"{exception.GetType().FullName}: {exception.Message}";
}
